from django.contrib.auth.models import User
from django.conf import settings
from django.db import models
from django.db.models.signals import post_init, pre_save, post_save

from core.models import Person, Invite
from django.dispatch import receiver
from task.mail import SendMail
from django.template.loader import render_to_string


def create_person(instance, sender, **kwargs):
    if not Person.objects.filter(auth_user=instance).first():
        Person.objects.create(
            legal_name=instance.first_name + ' ' + instance.last_name,
            name=instance.first_name + ' ' + instance.last_name,
            is_lawyer=False,
            legal_type='F',
            alter_user=instance,
            auth_user=instance,
            create_user=instance,
            is_active=True,
            is_customer=False,
            is_supplier=False,
            import_from_legacy=False,
            legacy_code=''
        )


@receiver(post_save, sender=Invite)
def send_invite_email(instance, sender, **kwargs):
    project_link = settings.PROJECT_LINK
    mail = SendMail()
    mail.subject = 'Easy Lawyer - Convite para cadastro'
    mail.message = render_to_string('core/mail/base.html',
                                    {'server': project_link,
                                     'pk': instance.pk,
                                     'project_name': settings.PROJECT_NAME,
                                     'invite': instance
                                     })
    mail.to_mail = [instance.email]

    # TODO: tratar corretamente a excecao

    try:
        mail.send()
    except Exception as e:
        print(e)
        print('VocÃª tentou mandar um e-mail')


models.signals.post_save.connect(create_person, sender=User, dispatch_uid='create_person')
